Workbook

Sheet Input&Output
A1: ECONOMIC EVALUATION STUDY
A2: FIELD ( ) DEVELOPMENT PROJECT
A4: Production Data
A5: Oil production rate in year 1 | D5: 20 | E5: MBD
A6: Decline rate | D6: 5 | E6: %
A7: Gas Oil Ratio | D7: 1500 | E7: SCF/STB
A9: Investment Data
A10: Number of wells | D10: 30 | E10: wells
A11: Drilling cost | D11: 5 | E11: $MM/well
A12: Length of pipelines | D12: 30 | E12: Kilometer
A13: Diameter of crude pipeline | D13: 8 | E13: inches
A14: Diameter of gas pipeline | D14: 12 | E14: inches
A15: Cost of pipeline | D15: 15000 | E15: $/inch-kilometer
A16: Cost of production facilities | D16: 50 | E16: $MM
A17: Cost of camp | D17: 10 | E17: $MM
A19: Operating Cost Data (@ year 0) | G19: Inflation rate (%/year) | I19: t
A20: Fuel | D20: 1 | E20: $MM/year | G20: 2
A21: Spare parts | D21: 3 | E21: $MM/year | G21: 5
A22: Maintenance Requirements | D22: 5 | E22: $MM/year | G22: 6
A23: Salaries | D23: 1000 | E23: $/person/month | G23: 1
A24: Catering & Services | D24: 200 | E24: $/person/day | G24: 10
A25: Overhead costs | D25: 2 | E25: $MM/year | G25: 7
A26: Well services & workovers | D26: 1 | E26: $MM/year/well | G26: 7
A27: Number of personnel | D27: 30 | E27: People
A29: Cash Flow Data | G29: Escalation rate (%/year)
A30: Crude selling Price | D30: 20 | E30: $/barrel | G30: 2
A31: Gas selling Price | D31: 1.5 | E31: $/MCF | G31: 0
A32: Tax rate | D32: 40 | E32: %
A33: Discount Rate | D33: 10 | E33: %
A35: Depreciation Data
A36: Depreciation Method | D36: Str. Line | E36: DBw/B | F36: DB | G36: DDBw/B | H36: DDB | I36: S.Y.D | J36: Unt. Prod
A37: (Enter 1) | D37: 1
A38: Number of Years | D38: 10
A39: Salvage Value
A41: Other Assumptions
A42: Project life = 20 years
A43: No abandonment cost
J44: Result
A45: Economic Indicators | D45: Net Present Value (NPV) | H45: ='Cash Flow'!AU30 -> 24.31446 | I45: $MM | J45: =IF(H45>0,"OK","Not OK") -> OK
D46: Internal Rate of Return (IRR) | H46: =IRR('Cash Flow'!AS8:AS28) -> 0.06255686 | J46: =IF(H46>D33/100,"OK","Not OK") -> Not OK
...

Sheet Cash Flow
A1: CASH FLOW ANALYSIS ($MM) | AM1: CASH FLOW ANALYSIS
AM2: (Table 2)
A4: Years | C4: Annual Production | F4: Revenue | K4: CAPEX | M4: OPEX | W4: Tax Calculation | AM4: Years | AO4: Cash Flow | AW4: Cum. | AX4: Payback | AZ4: Discounted NCF
C5: Oil | D5: Gas | F5: Oil | G5: Gas | I5: Total | M5: Fuel | N5: Spares | O5: Maint. | P5: Salaries | Q5: Serv. | R5: O/H | S5: Wells | U5: Total | W5: Revenue | X5: St. Line | Y5: DB w/Balloon | AA5: Dec | AB5: DDBw/Balloon | AD5: Double | AE5: SYD | AF5: Unit of Prod | AG5: Dep. | AH5: Opex | AI5: Net Rev. | AJ5: W/LCF | AK5: Income | AL5: Tax | AO5: Revenue | AP5: Capex | AQ5: Opex | AR5: Tax | AS5: NCF | AU5: NPV | AW5: CF | AX5: (Years) | AZ5: 0 | BA5: 0.2 | BB5: 0.4 | BC5: 0.6 | BD5: 0.8 | BE5: 1
C6: (MMB) | D6: (BCF) | Y6: Bal | Z6: Dep | AA6: Bal | AB6: Bal | AC6: Dep | AD6: Dec. Bal | BF6: =AK9-AL9+AG9 -> 78.32544
A8: 0 | K8: =SUM(('Input&Output'!$D$10*'Input&Output'!$D$11)+(('Input&Output'!$D$12*('Input&Output'!$D$13+'Input&Output'!$D$14)*'Input&Output'!$D$15)/1000000)+('Input&Output'!$D$16)+('Input&Output'!$D$17)) -> 219 | M8: ='Input&Output'!D20 -> 1 | N8: ='Input&Output'!D21 -> 3 | O8: ='Input&Output'!D22 -> 5 | P8: ='Input&Output'!D23 -> 1000 | Q8: ='Input&Output'!D24 -> 200 | R8: ='Input&Output'!D25 -> 2 | S8: ='Input&Output'!D10 -> 30 | AM8: 0 | AP8: =K8 -> 219 | AS8: =AO8-AP8-AQ8-AR8 -> -219 | AU8: =AS8/(1+'Input&Output'!$D$33/100)^A8 -> -219 | AW8: =AS8 -> -219 | AX8: =IF(AND(AW9>0,AW8<0),A8+ABS(AW8/AS9),0) -> 0 | AZ8: =AS8 -> -219 | BA8: =AS8 -> -219 | BB8: =AS8 -> -219 | BC8: =AS8 -> -219 | BD8: =AS8 -> -219 | BE8: =AS8 -> -219
A9: 1 | C9: ='Input&Output'!$D$5*365/1000 -> 7.3 | D9: =C9*'Input&Output'!$D$7/1000 -> 10.95 | F9: ='Input&Output'!$D$30*'Cash Flow'!C9 -> 146 | G9: ='Input&Output'!$D$31*'Cash Flow'!D9 -> 16.425 | I9: =F9+G9 -> 162.425 | M9: ='Input&Output'!$D$20*(1+('Input&Output'!$G$20/100))^$A9 -> 1.02 | N9: ='Input&Output'!$D$21*(1+('Input&Output'!$G$21/100))^$A9 -> 3.15 | O9: ='Input&Output'!$D$22*(1+('Input&Output'!$G$22/100))^$A9 -> 5.3 | P9: =('Input&Output'!$D$23*'Input&Output'!$D$27*12/1000000)*(1+('Input&Output'!$G$23/100))^$A9 -> 0.3636 | Q9: =('Input&Output'!$D$24*'Input&Output'!$D$27*365/1000000)*((1+('Input&Output'!$G$24/100))^$A9) -> 2.409 | R9: ='Input&Output'!$D$25*((1+('Input&Output'!$G$25/100))^$A9) -> 2.14 | S9: ='Input&Output'!$D$10*'Input&Output'!$D$26*(1+('Input&Output'!$G$26/100))^$A9 -> 32.1 | T9: =SUM(M9:S9) -> 46.4826 | U9: =SUM(M9:S9) -> 46.4826 | W9: =F9+G9 -> 162.425 | AG9: =IF(A9<='Input&Output'!$D$38,'Cash Flow'!$K$8/'Input&Output'!$D$38,0) -> 21.9 | AH9: =SUM(M9:S9) -> 46.4826 | AK9: =MAX(0,W9-AH9-AG9) -> 94.0424 | AL9: =AK9*('Input&Output'!$D$32/100) -> 37.61696 | AM9: =AM8+1 -> 1 | AO9: =F9+G9 -> 162.425 | AQ9: =SUM(M9:S9) -> 46.4826 | AR9: =AK9*('Input&Output'!$D$32/100) -> 37.61696 | AS9: =AO9-AP9-AQ9-AR9 -> 78.32544 | AU9: =AS9/(1+'Input&Output'!$D$33/100)^A9 -> 71.204945 | AW9: =AW8+AS9 -> -140.67456 | AX9: =IF(AND(AW10>0,AW9<0),A9+ABS(AW9/AS10),0) -> 0 | AZ9: =AS9/(1+(0/100))^A9 -> 78.32544 | BA9: =AS9/(1+(20/100))^A9 -> 65.2712 | BB9: =AS9/(1+(40/100))^A9 -> 55.946743 | BC9: =AS9/(1+(60/100))^A9 -> 48.9534 | BD9: =AS9/(1+(80/100))^A9 -> 43.514133 | BE9: =AS9/(1+(100/100))^A9 -> 39.16272
A10: 2 | C10: =C9*(1-'Input&Output'!$D$6/100) -> 6.935 | D10: =C10*'Input&Output'!$D$7/1000 -> 10.4025 | F10: ='Input&Output'!$D$30*'Cash Flow'!C10 -> 138.7 | G10: ='Input&Output'!$D$31*'Cash Flow'!D10 -> 15.60375 | I10: =F10+G10 -> 154.30375 | M10: ='Input&Output'!$D$20*(1+('Input&Output'!$G$20/100))^$A10 -> 1.0404 | N10: ='Input&Output'!$D$21*(1+('Input&Output'!$G$21/100))^$A10 -> 3.3075 | O10: ='Input&Output'!$D$22*(1+('Input&Output'!$G$22/100))^$A10 -> 5.618 | P10: =('Input&Output'!$D$23*'Input&Output'!$D$27*12/1000000)*(1+('Input&Output'!$G$23/100))^$A10 -> 0.367236 | Q10: =('Input&Output'!$D$24*'Input&Output'!$D$27*365/1000000)*((1+('Input&Output'!$G$24/100))^$A10) -> 2.6499 | R10: ='Input&Output'!$D$25*((1+('Input&Output'!$G$25/100))^$A10) -> 2.2898 | S10: ='Input&Output'!$D$10*'Input&Output'!$D$26*(1+('Input&Output'!$G$26/100))^$A10 -> 34.347 | T10: =SUM(M10:S10) -> 49.619836 | U10: =SUM(M10:S10) -> 49.619836 | W10: =F10+G10 -> 154.30375 | AG10: =IF(A10<='Input&Output'!$D$38,'Cash Flow'!$K$8/'Input&Output'!$D$38,0) -> 21.9 | AH10: =SUM(M10:S10) -> 49.619836 | AK10: =MAX(0,W10-AH10-AG10) -> 82.783914 | AL10: =AK10*('Input&Output'!$D$32/100) -> 33.113566 | AM10: =AM9+1 -> 2 | AO10: =F10+G10 -> 154.30375 | AQ10: =SUM(M10:S10) -> 49.619836 | AR10: =AK10*('Input&Output'!$D$32/100) -> 33.113566 | AS10: =AO10-AP10-AQ10-AR10 -> 71.570348 | AU10: =AS10/(1+'Input&Output'!$D$33/100)^A10 -> 59.149048 | AW10: =AW9+AS10 -> -69.104212 | AX10: =IF(AND(AW11>0,AW10<0),A10+ABS(AW10/AS11),0) -> 0 | AZ10: =AS10/(1+(0/100))^A10 -> 71.570348 | BA10: =AS10/(1+(20/100))^A10 -> 49.701631 | BB10: =AS10/(1+(40/100))^A10 -> 36.515484 | BC10: =AS10/(1+(60/100))^A10 -> 27.957167 | BD10: =AS10/(1+(80/100))^A10 -> 22.089614 | BE10: =AS10/(1+(100/100))^A10 -> 17.892587
A11: 3 | C11: =C10*(1-'Input&Output'!$D$6/100) -> 6.58825 | D11: =C11*'Input&Output'!$D$7/1000 -> 9.882375 | F11: ='Input&Output'!$D$30*'Cash Flow'!C11 -> 131.765 | G11: ='Input&Output'!$D$31*'Cash Flow'!D11 -> 14.823562 | I11: =F11+G11 -> 146.58856 | M11: ='Input&Output'!$D$20*(1+('Input&Output'!$G$20/100))^$A11 -> 1.061208 | N11: ='Input&Output'!$D$21*(1+('Input&Output'!$G$21/100))^$A11 -> 3.472875 | O11: ='Input&Output'!$D$22*(1+('Input&Output'!$G$22/100))^$A11 -> 5.95508 | P11: =('Input&Output'!$D$23*'Input&Output'!$D$27*12/1000000)*(1+('Input&Output'!$G$23/100))^$A11 -> 0.37090836 | Q11: =('Input&Output'!$D$24*'Input&Output'!$D$27*365/1000000)*((1+('Input&Output'!$G$24/100))^$A11) -> 2.91489 | R11: ='Input&Output'!$D$25*((1+('Input&Output'!$G$25/100))^$A11) -> 2.450086 | S11: ='Input&Output'!$D$10*'Input&Output'!$D$26*(1+('Input&Output'!$G$26/100))^$A11 -> 36.75129 | T11: =SUM(M11:S11) -> 52.976337 | U11: =SUM(M11:S11) -> 52.976337 | W11: =F11+G11 -> 146.58856 | AG11: =IF(A11<='Input&Output'!$D$38,'Cash Flow'!$K$8/'Input&Output'!$D$38,0) -> 21.9 | AH11: =SUM(M11:S11) -> 52.976337 | AK11: =MAX(0,W11-AH11-AG11) -> 71.712225 | AL11: =AK11*('Input&Output'!$D$32/100) -> 28.68489 | AM11: =AM10+1 -> 3 | AO11: =F11+G11 -> 146.58856 | AQ11: =SUM(M11:S11) -> 52.976337 | AR11: =AK11*('Input&Output'!$D$32/100) -> 28.68489 | AS11: =AO11-AP11-AQ11-AR11 -> 64.927335 | AU11: =AS11/(1+'Input&Output'!$D$33/100)^A11 -> 48.780868 | AW11: =AW10+AS11 -> -4.1768765 | AX11: =IF(AND(AW12>0,AW11<0),A11+ABS(AW11/AS12),0) -> 3.0715527 | AZ11: =AS11/(1+(0/100))^A11 -> 64.927335 | BA11: =AS11/(1+(20/100))^A11 -> 37.573689 | BB11: =AS11/(1+(40/100))^A11 -> 23.661565 | BC11: =AS11/(1+(60/100))^A11 -> 15.8514 | BD11: =AS11/(1+(80/100))^A11 -> 11.132945 | BE11: =AS11/(1+(100/100))^A11 -> 8.1159169
A12: 4 | C12: =C11*(1-'Input&Output'!$D$6/100) -> 6.2588375 | D12: =C12*'Input&Output'!$D$7/1000 -> 9.3882562 | F12: ='Input&Output'!$D$30*'Cash Flow'!C12 -> 125.17675 | G12: ='Input&Output'!$D$31*'Cash Flow'!D12 -> 14.082384 | I12: =F12+G12 -> 139.25913 | M12: ='Input&Output'!$D$20*(1+('Input&Output'!$G$20/100))^$A12 -> 1.0824322 | N12: ='Input&Output'!$D$21*(1+('Input&Output'!$G$21/100))^$A12 -> 3.6465188 | O12: ='Input&Output'!$D$22*(1+('Input&Output'!$G$22/100))^$A12 -> 6.3123848 | P12: =('Input&Output'!$D$23*'Input&Output'!$D$27*12/1000000)*(1+('Input&Output'!$G$23/100))^$A12 -> 0.37461744 | Q12: =('Input&Output'!$D$24*'Input&Output'!$D$27*365/1000000)*((1+('Input&Output'!$G$24/100))^$A12) -> 3.206379 | R12: ='Input&Output'!$D$25*((1+('Input&Output'!$G$25/100))^$A12) -> 2.621592 | S12: ='Input&Output'!$D$10*'Input&Output'!$D$26*(1+('Input&Output'!$G$26/100))^$A12 -> 39.32388 | T12: =SUM(M12:S12) -> 56.567804 | U12: =SUM(M12:S12) -> 56.567804 | W12: =F12+G12 -> 139.25913 | AG12: =IF(A12<='Input&Output'!$D$38,'Cash Flow'!$K$8/'Input&Output'!$D$38,0) -> 21.9 | AH12: =SUM(M12:S12) -> 56.567804 | AK12: =MAX(0,W12-AH12-AG12) -> 60.79133 | AL12: =AK12*('Input&Output'!$D$32/100) -> 24.316532 | AM12: =AM11+1 -> 4 | AO12: =F12+G12 -> 139.25913 | AQ12: =SUM(M12:S12) -> 56.567804 | AR12: =AK12*('Input&Output'!$D$32/100) -> 24.316532 | AS12: =AO12-AP12-AQ12-AR12 -> 58.374798 | AU12: =AS12/(1+'Input&Output'!$D$33/100)^A12 -> 39.870772 | AW12: =AW11+AS12 -> 54.197921 | AX12: =IF(AND(AW13>0,AW12<0),A12+ABS(AW12/AS13),0) -> 0 | AZ12: =AS12/(1+(0/100))^A12 -> 58.374798 | BA12: =AS12/(1+(20/100))^A12 -> 28.151426 | BB12: =AS12/(1+(40/100))^A12 -> 15.195439 | BC12: =AS12/(1+(60/100))^A12 -> 8.9072873 | BD12: =AS12/(1+(80/100))^A12 -> 5.5607756 | BE12: =AS12/(1+(100/100))^A12 -> 3.6484249
A13: 5 | C13: =C12*(1-'Input&Output'!$D$6/100) -> 5.9458956 | D13: =C13*'Input&Output'!$D$7/1000 -> 8.9188434 | F13: ='Input&Output'!$D$30*'Cash Flow'!C13 -> 118.91791 | G13: ='Input&Output'!$D$31*'Cash Flow'!D13 -> 13.378265 | I13: =F13+G13 -> 132.29618 | M13: ='Input&Output'!$D$20*(1+('Input&Output'!$G$20/100))^$A13 -> 1.1040808 | N13: ='Input&Output'!$D$21*(1+('Input&Output'!$G$21/100))^$A13 -> 3.8288447 | O13: ='Input&Output'!$D$22*(1+('Input&Output'!$G$22/100))^$A13 -> 6.6911279 | P13: =('Input&Output'!$D$23*'Input&Output'!$D$27*12/1000000)*(1+('Input&Output'!$G$23/100))^$A13 -> 0.37836362 | Q13: =('Input&Output'!$D$24*'Input&Output'!$D$27*365/1000000)*((1+('Input&Output'!$G$24/100))^$A13) -> 3.5270169 | R13: ='Input&Output'!$D$25*((1+('Input&Output'!$G$25/100))^$A13) -> 2.8051035 | S13: ='Input&Output'!$D$10*'Input&Output'!$D$26*(1+('Input&Output'!$G$26/100))^$A13 -> 42.076552 | T13: =SUM(M13:S13) -> 60.411089 | U13: =SUM(M13:S13) -> 60.411089 | W13: =F13+G13 -> 132.29618 | AG13: =IF(A13<='Input&Output'!$D$38,'Cash Flow'!$K$8/'Input&Output'!$D$38,0) -> 21.9 | AH13: =SUM(M13:S13) -> 60.411089 | AK13: =MAX(0,W13-AH13-AG13) -> 49.985088 | AL13: =AK13*('Input&Output'!$D$32/100) -> 19.994035 | AM13: =AM12+1 -> 5 | AO13: =F13+G13 -> 132.29618 | AQ13: =SUM(M13:S13) -> 60.411089 | AR13: =AK13*('Input&Output'!$D$32/100) -> 19.994035 | AS13: =AO13-AP13-AQ13-AR13 -> 51.891053 | AU13: =AS13/(1+'Input&Output'!$D$33/100)^A13 -> 32.220261 | AW13: =AW12+AS13 -> 106.08897 | AX13: =IF(AND(AW14>0,AW13<0),A13+ABS(AW13/AS14),0) -> 0 | AZ13: =AS13/(1+(0/100))^A13 -> 51.891053 | BA13: =AS13/(1+(20/100))^A13 -> 20.85385 | BB13: =AS13/(1+(40/100))^A13 -> 9.6483335 | BC13: =AS13/(1+(60/100))^A13 -> 4.9487165 | BD13: =AS13/(1+(80/100))^A13 -> 2.7461861 | BE13: =AS13/(1+(100/100))^A13 -> 1.6215954
A14: 6 | C14: =C13*(1-'Input&Output'!$D$6/100) -> 5.6486008 | D14: =C14*'Input&Output'!$D$7/1000 -> 8.4729013 | F14: ='Input&Output'!$D$30*'Cash Flow'!C14 -> 112.97202 | G14: ='Input&Output'!$D$31*'Cash Flow'!D14 -> 12.709352 | I14: =F14+G14 -> 125.68137 | M14: ='Input&Output'!$D$20*(1+('Input&Output'!$G$20/100))^$A14 -> 1.1261624 | N14: ='Input&Output'!$D$21*(1+('Input&Output'!$G$21/100))^$A14 -> 4.0202869 | O14: ='Input&Output'!$D$22*(1+('Input&Output'!$G$22/100))^$A14 -> 7.0925956 | P14: =('Input&Output'!$D$23*'Input&Output'!$D$27*12/1000000)*(1+('Input&Output'!$G$23/100))^$A14 -> 0.38214725 | Q14: =('Input&Output'!$D$24*'Input&Output'!$D$27*365/1000000)*((1+('Input&Output'!$G$24/100))^$A14) -> 3.8797186 | R14: ='Input&Output'!$D$25*((1+('Input&Output'!$G$25/100))^$A14) -> 3.0014607 | S14: ='Input&Output'!$D$10*'Input&Output'!$D$26*(1+('Input&Output'!$G$26/100))^$A14 -> 45.021911 | T14: =SUM(M14:S14) -> 64.524282 | U14: =SUM(M14:S14) -> 64.524282 | W14: =F14+G14 -> 125.68137 | AG14: =IF(A14<='Input&Output'!$D$38,'Cash Flow'!$K$8/'Input&Output'!$D$38,0) -> 21.9 | AH14: =SUM(M14:S14) -> 64.524282 | AK14: =MAX(0,W14-AH14-AG14) -> 39.257087 | AL14: =AK14*('Input&Output'!$D$32/100) -> 15.702835 | AM14: =AM13+1 -> 6 | AO14: =F14+G14 -> 125.68137 | AQ14: =SUM(M14:S14) -> 64.524282 | AR14: =AK14*('Input&Output'!$D$32/100) -> 15.702835 | AS14: =AO14-AP14-AQ14-AR14 -> 45.454252 | AU14: =AS14/(1+'Input&Output'!$D$33/100)^A14 -> 25.65774 | AW14: =AW13+AS14 -> 151.54323 | AX14: =IF(AND(AW15>0,AW14<0),A14+ABS(AW14/AS15),0) -> 0 | AZ14: =AS14/(1+(0/100))^A14 -> 45.454252 | BA14: =AS14/(1+(20/100))^A14 -> 15.222537 | BB14: =AS14/(1+(40/100))^A14 -> 6.0367932 | BC14: =AS14/(1+(60/100))^A14 -> 2.7092845 | BD14: =AS14/(1+(80/100))^A14 -> 1.3364093 | BE14: =AS14/(1+(100/100))^A14 -> 0.71022269
A15: 7 | C15: =C14*(1-'Input&Output'!$D$6/100) -> 5.3661708 | D15: =C15*'Input&Output'!$D$7/1000 -> 8.0492562 | F15: ='Input&Output'!$D$30*'Cash Flow'!C15 -> 107.32342 | G15: ='Input&Output'!$D$31*'Cash Flow'!D15 -> 12.073884 | I15: =F15+G15 -> 119.3973 | M15: ='Input&Output'!$D$20*(1+('Input&Output'!$G$20/100))^$A15 -> 1.1486857 | N15: ='Input&Output'!$D$21*(1+('Input&Output'!$G$21/100))^$A15 -> 4.2213013 | O15: ='Input&Output'!$D$22*(1+('Input&Output'!$G$22/100))^$A15 -> 7.5181513 | P15: =('Input&Output'!$D$23*'Input&Output'!$D$27*12/1000000)*(1+('Input&Output'!$G$23/100))^$A15 -> 0.38596873 | Q15: =('Input&Output'!$D$24*'Input&Output'!$D$27*365/1000000)*((1+('Input&Output'!$G$24/100))^$A15) -> 4.2676904 | R15: ='Input&Output'!$D$25*((1+('Input&Output'!$G$25/100))^$A15) -> 3.211563 | S15: ='Input&Output'!$D$10*'Input&Output'!$D$26*(1+('Input&Output'!$G$26/100))^$A15 -> 48.173444 | T15: =SUM(M15:S15) -> 68.926805 | U15: =SUM(M15:S15) -> 68.926805 | W15: =F15+G15 -> 119.3973 | AG15: =IF(A15<='Input&Output'!$D$38,'Cash Flow'!$K$8/'Input&Output'!$D$38,0) -> 21.9 | AH15: =SUM(M15:S15) -> 68.926805 | AK15: =MAX(0,W15-AH15-AG15) -> 28.570496 | AL15: =AK15*('Input&Output'!$D$32/100) -> 11.428198 | AM15: =AM14+1 -> 7 | AO15: =F15+G15 -> 119.3973 | AQ15: =SUM(M15:S15) -> 68.926805 | AR15: =AK15*('Input&Output'!$D$32/100) -> 11.428198 | AS15: =AO15-AP15-AQ15-AR15 -> 39.042297 | AU15: =AS15/(1+'Input&Output'!$D$33/100)^A15 -> 20.034872 | AW15: =AW14+AS15 -> 190.58552 | AX15: =IF(AND(AW16>0,AW15<0),A15+ABS(AW15/AS16),0) -> 0 | AZ15: =AS15/(1+(0/100))^A15 -> 39.042297 | BA15: =AS15/(1+(20/100))^A15 -> 10.895989 | BB15: =AS15/(1+(40/100))^A15 -> 3.7037283 | BC15: =AS15/(1+(60/100))^A15 -> 1.4544389 | BD15: =AS15/(1+(80/100))^A15 -> 0.63771676 | BE15: =AS15/(1+(100/100))^A15 -> 0.30501795
A16: 8 | C16: =C15*(1-'Input&Output'!$D$6/100) -> 5.0978623 | D16: =C16*'Input&Output'!$D$7/1000 -> 7.6467934 | F16: ='Input&Output'!$D$30*'Cash Flow'!C16 -> 101.95725 | G16: ='Input&Output'!$D$31*'Cash Flow'!D16 -> 11.47019 | I16: =F16+G16 -> 113.42744 | M16: ='Input&Output'!$D$20*(1+('Input&Output'!$G$20/100))^$A16 -> 1.1716594 | N16: ='Input&Output'!$D$21*(1+('Input&Output'!$G$21/100))^$A16 -> 4.4323663 | O16: ='Input&Output'!$D$22*(1+('Input&Output'!$G$22/100))^$A16 -> 7.9692404 | P16: =('Input&Output'!$D$23*'Input&Output'!$D$27*12/1000000)*(1+('Input&Output'!$G$23/100))^$A16 -> 0.38982841 | Q16: =('Input&Output'!$D$24*'Input&Output'!$D$27*365/1000000)*((1+('Input&Output'!$G$24/100))^$A16) -> 4.6944595 | R16: ='Input&Output'!$D$25*((1+('Input&Output'!$G$25/100))^$A16) -> 3.4363724 | S16: ='Input&Output'!$D$10*'Input&Output'!$D$26*(1+('Input&Output'!$G$26/100))^$A16 -> 51.545585 | T16: =SUM(M16:S16) -> 73.639512 | U16: =SUM(M16:S16) -> 73.639512 | W16: =F16+G16 -> 113.42744 | AG16: =IF(A16<='Input&Output'!$D$38,'Cash Flow'!$K$8/'Input&Output'!$D$38,0) -> 21.9 | AH16: =SUM(M16:S16) -> 73.639512 | AK16: =MAX(0,W16-AH16-AG16) -> 17.887924 | AL16: =AK16*('Input&Output'!$D$32/100) -> 7.1551694 | AM16: =AM15+1 -> 8 | AO16: =F16+G16 -> 113.42744 | AQ16: =SUM(M16:S16) -> 73.639512 | AR16: =AK16*('Input&Output'!$D$32/100) -> 7.1551694 | AS16: =AO16-AP16-AQ16-AR16 -> 32.632754 | AU16: =AS16/(1+'Input&Output'!$D$33/100)^A16 -> 15.223421 | AW16: =AW15+AS16 -> 223.21828 | AX16: =IF(AND(AW17>0,AW16<0),A16+ABS(AW16/AS17),0) -> 0 | AZ16: =AS16/(1+(0/100))^A16 -> 32.632754 | BA16: =AS16/(1+(20/100))^A16 -> 7.5893356 | BB16: =AS16/(1+(40/100))^A16 -> 2.2112072 | BC16: =AS16/(1+(60/100))^A16 -> 0.75979052 | BD16: =AS16/(1+(80/100))^A16 -> 0.29612406 | BE16: =AS16/(1+(100/100))^A16 -> 0.1274717
A17: 9 | C17: =C16*(1-'Input&Output'!$D$6/100) -> 4.8429691 | D17: =C17*'Input&Output'!$D$7/1000 -> 7.2644537 | F17: ='Input&Output'!$D$30*'Cash Flow'!C17 -> 96.859383 | G17: ='Input&Output'!$D$31*'Cash Flow'!D17 -> 10.896681 | I17: =F17+G17 -> 107.75606 | M17: ='Input&Output'!$D$20*(1+('Input&Output'!$G$20/100))^$A17 -> 1.1950926 | N17: ='Input&Output'!$D$21*(1+('Input&Output'!$G$21/100))^$A17 -> 4.6539846 | O17: ='Input&Output'!$D$22*(1+('Input&Output'!$G$22/100))^$A17 -> 8.4473948 | P17: =('Input&Output'!$D$23*'Input&Output'!$D$27*12/1000000)*(1+('Input&Output'!$G$23/100))^$A17 -> 0.3937267 | Q17: =('Input&Output'!$D$24*'Input&Output'!$D$27*365/1000000)*((1+('Input&Output'!$G$24/100))^$A17) -> 5.1639054 | R17: ='Input&Output'!$D$25*((1+('Input&Output'!$G$25/100))^$A17) -> 3.6769184 | S17: ='Input&Output'!$D$10*'Input&Output'!$D$26*(1+('Input&Output'!$G$26/100))^$A17 -> 55.153776 | T17: =SUM(M17:S17) -> 78.684799 | U17: =SUM(M17:S17) -> 78.684799 | W17: =F17+G17 -> 107.75606 | AG17: =IF(A17<='Input&Output'!$D$38,'Cash Flow'!$K$8/'Input&Output'!$D$38,0) -> 21.9 | AH17: =SUM(M17:S17) -> 78.684799 | AK17: =MAX(0,W17-AH17-AG17) -> 7.1712646 | AL17: =AK17*('Input&Output'!$D$32/100) -> 2.8685058 | AM17: =AM16+1 -> 9 | AO17: =F17+G17 -> 107.75606 | AQ17: =SUM(M17:S17) -> 78.684799 | AR17: =AK17*('Input&Output'!$D$32/100) -> 2.8685058 | AS17: =AO17-AP17-AQ17-AR17 -> 26.202759 | AU17: =AS17/(1+'Input&Output'!$D$33/100)^A17 -> 11.112528 | AW17: =AW16+AS17 -> 249.42104 | AX17: =IF(AND(AW18>0,AW17<0),A17+ABS(AW17/AS18),0) -> 0 | AZ17: =AS17/(1+(0/100))^A17 -> 26.202759 | BA17: =AS17/(1+(20/100))^A17 -> 5.0782702 | BB17: =AS17/(1+(40/100))^A17 -> 1.2682203 | BC17: =AS17/(1+(60/100))^A17 -> 0.38130032 | BD17: =AS17/(1+(80/100))^A17 -> 0.13209746 | BE17: =AS17/(1+(100/100))^A17 -> 0.051177263
A18: 10 | C18: =C17*(1-'Input&Output'!$D$6/100) -> 4.6008207 | D18: =C18*'Input&Output'!$D$7/1000 -> 6.901231 | F18: ='Input&Output'!$D$30*'Cash Flow'!C18 -> 92.016414 | G18: ='Input&Output'!$D$31*'Cash Flow'!D18 -> 10.351847 | I18: =F18+G18 -> 102.36826 | M18: ='Input&Output'!$D$20*(1+('Input&Output'!$G$20/100))^$A18 -> 1.2189944 | N18: ='Input&Output'!$D$21*(1+('Input&Output'!$G$21/100))^$A18 -> 4.8866839 | O18: ='Input&Output'!$D$22*(1+('Input&Output'!$G$22/100))^$A18 -> 8.9542385 | P18: =('Input&Output'!$D$23*'Input&Output'!$D$27*12/1000000)*(1+('Input&Output'!$G$23/100))^$A18 -> 0.39766397 | Q18: =('Input&Output'!$D$24*'Input&Output'!$D$27*365/1000000)*((1+('Input&Output'!$G$24/100))^$A18) -> 5.680296 | R18: ='Input&Output'!$D$25*((1+('Input&Output'!$G$25/100))^$A18) -> 3.9343027 | S18: ='Input&Output'!$D$10*'Input&Output'!$D$26*(1+('Input&Output'!$G$26/100))^$A18 -> 59.014541 | T18: =SUM(M18:S18) -> 84.08672 | U18: =SUM(M18:S18) -> 84.08672 | W18: =F18+G18 -> 102.36826 | AG18: =IF(A18<='Input&Output'!$D$38,'Cash Flow'!$K$8/'Input&Output'!$D$38,0) -> 21.9 | AH18: =SUM(M18:S18) -> 84.08672 | AK18: =MAX(0,W18-AH18-AG18) -> 0 | AL18: =AK18*('Input&Output'!$D$32/100) -> 0 | AM18: =AM17+1 -> 10 | AO18: =F18+G18 -> 102.36826 | AQ18: =SUM(M18:S18) -> 84.08672 | AR18: =AK18*('Input&Output'!$D$32/100) -> 0 | AS18: =AO18-AP18-AQ18-AR18 -> 18.28154 | AU18: =AS18/(1+'Input&Output'!$D$33/100)^A18 -> 7.0483251 | AW18: =AW17+AS18 -> 267.70258 | AX18: =IF(AND(AW19>0,AW18<0),A18+ABS(AW18/AS19),0) -> 0 | AZ18: =AS18/(1+(0/100))^A18 -> 18.28154 | BA18: =AS18/(1+(20/100))^A18 -> 2.9525708 | BB18: =AS18/(1+(40/100))^A18 -> 0.63202233 | BC18: =AS18/(1+(60/100))^A18 -> 0.16626964 | BD18: =AS18/(1+(80/100))^A18 -> 0.051202095 | BE18: =AS18/(1+(100/100))^A18 -> 0.017853067
A19: 11 | C19: =C18*(1-'Input&Output'!$D$6/100) -> 4.3707797 | D19: =C19*'Input&Output'!$D$7/1000 -> 6.5561695 | F19: ='Input&Output'!$D$30*'Cash Flow'!C19 -> 87.415593 | G19: ='Input&Output'!$D$31*'Cash Flow'!D19 -> 9.8342542 | I19: =F19+G19 -> 97.249847 | M19: ='Input&Output'!$D$20*(1+('Input&Output'!$G$20/100))^$A19 -> 1.2433743 | N19: ='Input&Output'!$D$21*(1+('Input&Output'!$G$21/100))^$A19 -> 5.1310181 | O19: ='Input&Output'!$D$22*(1+('Input&Output'!$G$22/100))^$A19 -> 9.4914928 | P19: =('Input&Output'!$D$23*'Input&Output'!$D$27*12/1000000)*(1+('Input&Output'!$G$23/100))^$A19 -> 0.4016406 | Q19: =('Input&Output'!$D$24*'Input&Output'!$D$27*365/1000000)*((1+('Input&Output'!$G$24/100))^$A19) -> 6.2483256 | R19: ='Input&Output'!$D$25*((1+('Input&Output'!$G$25/100))^$A19) -> 4.2097039 | S19: ='Input&Output'!$D$10*'Input&Output'!$D$26*(1+('Input&Output'!$G$26/100))^$A19 -> 63.145559 | T19: =SUM(M19:S19) -> 89.871114 | U19: =SUM(M19:S19) -> 89.871114 | W19: =F19+G19 -> 97.249847 | AG19: =IF(A19<='Input&Output'!$D$38,'Cash Flow'!$K$8/'Input&Output'!$D$38,0) -> 0 | AH19: =SUM(M19:S19) -> 89.871114 | AK19: =MAX(0,W19-AH19-AG19) -> 7.3787335 | AL19: =AK19*('Input&Output'!$D$32/100) -> 2.9514934 | AM19: =AM18+1 -> 11 | AO19: =F19+G19 -> 97.249847 | AQ19: =SUM(M19:S19) -> 89.871114 | AR19: =AK19*('Input&Output'!$D$32/100) -> 2.9514934 | AS19: =AO19-AP19-AQ19-AR19 -> 4.4272401 | AU19: =AS19/(1+'Input&Output'!$D$33/100)^A19 -> 1.5517207 | AW19: =AW18+AS19 -> 272.12982 | AX19: =IF(AND(AW20>0,AW19<0),A19+ABS(AW19/AS20),0) -> 0 | AZ19: =AS19/(1+(0/100))^A19 -> 4.4272401 | BA19: =AS19/(1+(20/100))^A19 -> 0.59585333 | BB19: =AS19/(1+(40/100))^A19 -> 0.10932631 | BC19: =AS19/(1+(60/100))^A19 -> 0.025165946 | BD19: =AS19/(1+(80/100))^A19 -> 0.0068886722 | BE19: =AS19/(1+(100/100))^A19 -> 0.0021617383
A20: 12 | C20: =C19*(1-'Input&Output'!$D$6/100) -> 4.1522407 | D20: =C20*'Input&Output'!$D$7/1000 -> 6.228361 | F20: ='Input&Output'!$D$30*'Cash Flow'!C20 -> 83.044813 | G20: ='Input&Output'!$D$31*'Cash Flow'!D20 -> 9.3425415 | I20: =F20+G20 -> 92.387355 | M20: ='Input&Output'!$D$20*(1+('Input&Output'!$G$20/100))^$A20 -> 1.2682418 | N20: ='Input&Output'!$D$21*(1+('Input&Output'!$G$21/100))^$A20 -> 5.387569 | O20: ='Input&Output'!$D$22*(1+('Input&Output'!$G$22/100))^$A20 -> 10.060982 | P20: =('Input&Output'!$D$23*'Input&Output'!$D$27*12/1000000)*(1+('Input&Output'!$G$23/100))^$A20 -> 0.40565701 | Q20: =('Input&Output'!$D$24*'Input&Output'!$D$27*365/1000000)*((1+('Input&Output'!$G$24/100))^$A20) -> 6.8731581 | R20: ='Input&Output'!$D$25*((1+('Input&Output'!$G$25/100))^$A20) -> 4.5043832 | S20: ='Input&Output'!$D$10*'Input&Output'!$D$26*(1+('Input&Output'!$G$26/100))^$A20 -> 67.565748 | T20: =SUM(M20:S20) -> 96.065739 | U20: =SUM(M20:S20) -> 96.065739 | W20: =F20+G20 -> 92.387355 | AG20: =IF(A20<='Input&Output'!$D$38,'Cash Flow'!$K$8/'Input&Output'!$D$38,0) -> 0 | AH20: =SUM(M20:S20) -> 96.065739 | AK20: =MAX(0,W20-AH20-AG20) -> 0 | AL20: =AK20*('Input&Output'!$D$32/100) -> 0 | AM20: =AM19+1 -> 12 | AO20: =F20+G20 -> 92.387355 | AQ20: =SUM(M20:S20) -> 96.065739 | AR20: =AK20*('Input&Output'!$D$32/100) -> 0 | AS20: =AO20-AP20-AQ20-AR20 -> -3.6783841 | AU20: =AS20/(1+'Input&Output'!$D$33/100)^A20 -> -1.1720465 | AW20: =AW19+AS20 -> 268.45143 | AX20: =IF(AND(AW21>0,AW20<0),A20+ABS(AW20/AS21),0) -> 0 | AZ20: =AS20/(1+(0/100))^A20 -> -3.6783841 | BA20: =AS20/(1+(20/100))^A20 -> -0.41255526 | BB20: =AS20/(1+(40/100))^A20 -> -0.064881466 | BC20: =AS20/(1+(60/100))^A20 -> -0.013068246 | BD20: =AS20/(1+(80/100))^A20 -> -0.0031797064 | BE20: =AS20/(1+(100/100))^A20 -> -0.000898043
A21: 13 | C21: =C20*(1-'Input&Output'!$D$6/100) -> 3.9446286 | D21: =C21*'Input&Output'!$D$7/1000 -> 5.916943 | F21: ='Input&Output'!$D$30*'Cash Flow'!C21 -> 78.892573 | G21: ='Input&Output'!$D$31*'Cash Flow'!D21 -> 8.8754144 | I21: =F21+G21 -> 87.767987 | M21: ='Input&Output'!$D$20*(1+('Input&Output'!$G$20/100))^$A21 -> 1.2936066 | N21: ='Input&Output'!$D$21*(1+('Input&Output'!$G$21/100))^$A21 -> 5.6569474 | O21: ='Input&Output'!$D$22*(1+('Input&Output'!$G$22/100))^$A21 -> 10.664641 | P21: =('Input&Output'!$D$23*'Input&Output'!$D$27*12/1000000)*(1+('Input&Output'!$G$23/100))^$A21 -> 0.40971358 | Q21: =('Input&Output'!$D$24*'Input&Output'!$D$27*365/1000000)*((1+('Input&Output'!$G$24/100))^$A21) -> 7.560474 | R21: ='Input&Output'!$D$25*((1+('Input&Output'!$G$25/100))^$A21) -> 4.81969 | S21: ='Input&Output'!$D$10*'Input&Output'!$D$26*(1+('Input&Output'!$G$26/100))^$A21 -> 72.29535 | T21: =SUM(M21:S21) -> 102.70042 | U21: =SUM(M21:S21) -> 102.70042 | W21: =F21+G21 -> 87.767987 | AG21: =IF(A21<='Input&Output'!$D$38,'Cash Flow'!$K$8/'Input&Output'!$D$38,0) -> 0 | AH21: =SUM(M21:S21) -> 102.70042 | AK21: =MAX(0,W21-AH21-AG21) -> 0 | AL21: =AK21*('Input&Output'!$D$32/100) -> 0 | AM21: =AM20+1 -> 13 | AO21: =F21+G21 -> 87.767987 | AQ21: =SUM(M21:S21) -> 102.70042 | AR21: =AK21*('Input&Output'!$D$32/100) -> 0 | AS21: =AO21-AP21-AQ21-AR21 -> -14.932436 | AU21: =AS21/(1+'Input&Output'!$D$33/100)^A21 -> -4.3253947 | AW21: =AW20+AS21 -> 253.519 | AX21: =IF(AND(AW22>0,AW21<0),A21+ABS(AW21/AS22),0) -> 0 | AZ21: =AS21/(1+(0/100))^A21 -> -14.932436 | BA21: =AS21/(1+(20/100))^A21 -> -1.3956434 | BB21: =AS21/(1+(40/100))^A21 -> -0.18813352 | BC21: =AS21/(1+(60/100))^A21 -> -0.033156668 | BD21: =AS21/(1+(80/100))^A21 -> -0.0071711381 | BE21: =AS21/(1+(100/100))^A21 -> -0.0018228071
... A28: 20 | C28: =C27*(1-'Input&Output'!$D$6/100) -> 2.7546813 | D28: =C28*'Input&Output'!$D$7/1000 -> 4.1320219 | F28: ='Input&Output'!$D$30*'Cash Flow'!C28 -> 55.093626 | G28: ='Input&Output'!$D$31*'Cash Flow'!D28 -> 6.1980329 | I28: =F28+G28 -> 61.291659 | M28: ='Input&Output'!$D$20*(1+('Input&Output'!$G$20/100))^$A28 -> 1.4859474 | N28: ='Input&Output'!$D$21*(1+('Input&Output'!$G$21/100))^$A28 -> 7.9598931 | O28: ='Input&Output'!$D$22*(1+('Input&Output'!$G$22/100))^$A28 -> 16.035677 | P28: =('Input&Output'!$D$23*'Input&Output'!$D$27*12/1000000)*(1+('Input&Output'!$G$23/100))^$A28 -> 0.43926841 | Q28: =('Input&Output'!$D$24*'Input&Output'!$D$27*365/1000000)*((1+('Input&Output'!$G$24/100))^$A28) -> 14.733225 | R28: ='Input&Output'!$D$25*((1+('Input&Output'!$G$25/100))^$A28) -> 7.7393689 | S28: ='Input&Output'!$D$10*'Input&Output'!$D$26*(1+('Input&Output'!$G$26/100))^$A28 -> 116.09053 | T28: =SUM(M28:S28) -> 164.48391 | U28: =SUM(M28:S28) -> 164.48391 | W28: =F28+G28 -> 61.291659 | AG28: =IF(A28<='Input&Output'!$D$38,'Cash Flow'!$K$8/'Input&Output'!$D$38,0) -> 0 | AH28: =SUM(M28:S28) -> 164.48391 | AK28: =MAX(0,W28-AH28-AG28) -> 0 | AL28: =AK28*('Input&Output'!$D$32/100) -> 0 | AM28: =AM27+1 -> 20 | AO28: =F28+G28 -> 61.291659 | AQ28: =SUM(M28:S28) -> 164.48391 | AR28: =AK28*('Input&Output'!$D$32/100) -> 0 | AS28: =AO28-AP28-AQ28-AR28 -> -103.19226 | AU28: =AS28/(1+'Input&Output'!$D$33/100)^A28 -> -15.338871 | AW28: =AW27+AS28 -> -192.44565 | AX28: =IF(AND(AW29>0,AW28<0),A28+ABS(AW28/AS29),0) -> 0 | AZ28: =AS28/(1+(0/100))^A28 -> -103.19226 | BA28: =AS28/(1+(20/100))^A28 -> -2.6916723 | BB28: =AS28/(1+(40/100))^A28 -> -0.12333501 | BC28: =AS28/(1+(60/100))^A28 -> -0.0085358633 | BD28: =AS28/(1+(80/100))^A28 -> -0.000809463 | BE28: =AS28/(1+(100/100))^A28 -> -9.8411803e-05
A30: Total | C30: =SUM(C9:C29) -> 93.661055 | D30: =SUM(D9:D29) -> 140.49158 | F30: =SUM(F9:F29) -> 1873.2211 | G30: =SUM(G9:G29) -> 210.73737 | I30: =SUM(I9:I29) -> 2083.9585 | M30: =SUM(M9:M29) -> 24.783317 | N30: =SUM(N9:N29) -> 104.15776 | O30: =SUM(O9:O29) -> 194.96363 | P30: =SUM(P9:P29) -> 8.0061099 | Q30: =SUM(Q9:Q29) -> 137.97547 | R30: =SUM(R9:R29) -> 87.730354 | S30: =SUM(S9:S29) -> 1315.9553 | U30: =SUM(U9:U29) -> 1873.5719 | W30: =SUM(W9:W29) -> 2083.9585 | AG30: =SUM(AG9:AG29) -> 219 | AH30: =SUM(AH9:AH29) -> 1873.5719 | AI30: =SUM(AI9:AI29) -> 0 | AK30: =SUM(AK9:AK29) -> 459.58046 | AL30: =SUM(AL9:AL29) -> 183.83218 | AM30: Total | AO30: =SUM(AO8:AO29) -> 2083.9585 | AP30: =SUM(AP8:AP29) -> 219 | AQ30: =SUM(AQ8:AQ29) -> 1873.5719 | AR30: =SUM(AR8:AR29) -> 183.83218 | AS30: =SUM(AS8:AS29) -> -192.44565 | AU30: =SUM(AU8:AU29) -> 24.31446 | AX30: =SUM(AX8:AX29) -> 3.0715527 | AZ30: =SUM(AZ8:AZ29) -> -192.44565 | BA30: =SUM(BA8:BA29) -> 4.6557519 | BB30: =SUM(BB8:BB29) -> -65.694836 | BC30: =SUM(BC8:BC29) -> -107.08678 | BD30: =SUM(BD8:BD29) -> -131.52999 | BE30: =SUM(BE8:BE29) -> -147.35216
AS32: NPV = | AU32: =AU30 -> 24.31446 | AV32: MM
AS33: IRR = | AU33: =IRR(AS8:AS28) -> 0.06255686
AS34: Payback = | AU34: =AX30 -> 3.0715527 | AV34: Years
AS35: CPI = | AU35: =AU32/AP8 -> 0.11102493 | AV35: $/$

Sheet Prod.=0.5
A1: CASH FLOW ANALYSIS ($MM) | AM1: CASH FLOW ANALYSIS
AM2: (Table 2)
A4: Years | C4: Annual Production | F4: Revenue | K4: CAPEX | M4: OPEX | W4: Tax Calculation | AM4: Years | AO4: Cash Flow | AW4: Cum. | AX4: Payback | AZ4: Discounted NCF
C5: Oil | D5: Gas | F5: Oil | G5: Gas | I5: Total | M5: Fuel | N5: Spares | O5: Maint. | P5: Salaries | Q5: Serv. | R5: O/H | S5: Wells | U5: Total | W5: Revenue | X5: St. Line | Y5: DB w/Balloon | AA5: Dec | AB5: DDBw/Balloon | AD5: Double | AE5: SYD | AF5: Unit of Prod | AG5: Dep. | AH5: Opex | AI5: Net Rev. | AJ5: W/LCF | AK5: Income | AL5: Tax | AO5: Revenue | AP5: Capex | AQ5: Opex | AR5: Tax | AS5: NCF | AU5: NPV | AW5: CF | AX5: (Years) | AZ5: 0 | BA5: 0.2 | BB5: 0.4 | BC5: 0.6 | BD5: 0.8 | BE5: 1
C6: (MMB) | D6: (BCF) | Y6: Bal | Z6: Dep | AA6: Bal | AB6: Bal | AC6: Dep | AD6: Dec. Bal
A8: 0 | K8: =SUM(('Input&Output'!$D$10*'Input&Output'!$D$11)+(('Input&Output'!$D$12*('Input&Output'!$D$13+'Input&Output'!$D$14)*'Input&Output'!$D$15)/1000000)+('Input&Output'!$D$16)+('Input&Output'!$D$17)) -> 219 | M8: ='Input&Output'!D20 -> 1 | N8: ='Input&Output'!D21 -> 3 | O8: ='Input&Output'!D22 -> 5 | P8: ='Input&Output'!D23 -> 1000 | Q8: ='Input&Output'!D24 -> 200 | R8: ='Input&Output'!D25 -> 2 | S8: ='Input&Output'!D10 -> 30 | AM8: 0 | AP8: =K8 -> 219 | AS8: =AO8-AP8-AQ8-AR8 -> -219 | AU8: =AS8/(1+'Input&Output'!$D$33/100)^A8 -> -219 | AW8: =AS8 -> -219 | AX8: =IF(AND(AW9>0,AW8<0),A8+ABS(AW8/AS9),0) -> 0 | AZ8: =$AS8/(1+AZ$5)^$A8 -> -219 | BA8: =$AS8/(1+BA$5)^$A8 -> -219 | BB8: =$AS8/(1+BB$5)^$A8 -> -219 | BC8: =$AS8/(1+BC$5)^$A8 -> -219 | BD8: =$AS8/(1+BD$5)^$A8 -> -219 | BE8: =$AS8/(1+BE$5)^$A8 -> -219
A9: 1 | C9: ='Input&Output'!$D$5*365*0.5/1000 -> 3.65 | D9: =C9*'Input&Output'!$D$7/1000 -> 5.475 | F9: ='Input&Output'!$D$30*C9 -> 73 | G9: ='Input&Output'!$D$30*D9 -> 109.5 | I9: =F9+G9 -> 182.5 | M9: ='Input&Output'!$D$20*(1+('Input&Output'!$G$20/100))^ROW(A1) -> 1.02 | N9: ='Input&Output'!$D$21*(1+('Input&Output'!$G$21/100))^ROW(A1) -> 3.15 | O9: ='Input&Output'!$D$22*(1+('Input&Output'!$G$22/100))^ROW(A1) -> 5.3 | P9: =('Input&Output'!$D$23*'Input&Output'!$D$27*12/1000000)*(1+('Input&Output'!$G$23/100))^ROW(A1) -> 0.3636 | Q9: =('Input&Output'!$D$24*'Input&Output'!$D$27*365/1000000)*((1+('Input&Output'!$G$24/100))^ROW(A1)) -> 2.409 | R9: ='Input&Output'!$D$25*((1+('Input&Output'!$G$25/100))^ROW(A1)) -> 2.14 | S9: ='Input&Output'!$D$10*'Input&Output'!$D$26*(1+('Input&Output'!$G$26/100))^ROW(A1) -> 32.1 | U9: =SUM(M9:S9) -> 46.4826 | W9: =I9 -> 182.5 | AG9: =IF(A9<='Input&Output'!$D$38,$K$8/'Input&Output'!$D$38,0) -> 21.9 | AH9: =U9 -> 46.4826 | AK9: =MAX(0,W9-AH9-AG9) -> 114.1174 | AL9: =AK9*('Input&Output'!$D$32/100) -> 45.64696 | AO9: =I9 -> 182.5 | AQ9: =U9 -> 46.4826 | AR9: =AL9 -> 45.64696 | AS9: =AO9-AP9-AQ9-AR9 -> 90.37044 | AU9: =AS9/(1+'Input&Output'!$D$33/100)^A9 -> 82.154945 | AW9: =AW8+AS9 -> -128.62956 | AX9: =IF(AND(AW10>0,AW9<0),A9+ABS(AW9/AS10),0) -> 0 | AZ9: =$AS9/(1+AZ$5)^$A9 -> 90.37044 | BA9: =$AS9/(1+BA$5)^$A9 -> 75.3087 | BB9: =$AS9/(1+BB$5)^$A9 -> 64.550314 | BC9: =$AS9/(1+BC$5)^$A9 -> 56.481525 | BD9: =$AS9/(1+BD$5)^$A9 -> 50.2058 | BE9: =$AS9/(1+BE$5)^$A9 -> 45.18522
A10: 2 | C10: =C9*(1-'Input&Output'!$D$6/100) -> 3.4675 | D10: =C10*'Input&Output'!$D$7/1000 -> 5.20125 | F10: ='Input&Output'!$D$30*C10 -> 69.35 | G10: ='Input&Output'!$D$30*D10 -> 104.025 | I10: =F10+G10 -> 173.375 | M10: ='Input&Output'!$D$20*(1+('Input&Output'!$G$20/100))^ROW(A2) -> 1.0404 | N10: ='Input&Output'!$D$21*(1+('Input&Output'!$G$21/100))^ROW(A2) -> 3.3075 | O10: ='Input&Output'!$D$22*(1+('Input&Output'!$G$22/100))^ROW(A2) -> 5.618 | P10: =('Input&Output'!$D$23*'Input&Output'!$D$27*12/1000000)*(1+('Input&Output'!$G$23/100))^ROW(A2) -> 0.367236 | Q10: =('Input&Output'!$D$24*'Input&Output'!$D$27*365/1000000)*((1+('Input&Output'!$G$24/100))^ROW(A2)) -> 2.6499 | R10: ='Input&Output'!$D$25*((1+('Input&Output'!$G$25/100))^ROW(A2)) -> 2.2898 | S10: ='Input&Output'!$D$10*'Input&Output'!$D$26*(1+('Input&Output'!$G$26/100))^ROW(A2) -> 34.347 | U10: =SUM(M10:S10) -> 49.619836 | W10: =I10 -> 173.375 | AG10: =IF(A10<='Input&Output'!$D$38,$K$8/'Input&Output'!$D$38,0) -> 21.9 | AH10: =U10 -> 49.619836 | AK10: =MAX(0,W10-AH10-AG10) -> 101.85516 | AL10: =AK10*('Input&Output'!$D$32/100) -> 40.742066 | AO10: =I10 -> 173.375 | AQ10: =U10 -> 49.619836 | AR10: =AL10 -> 40.742066 | AS10: =AO10-AP10-AQ10-AR10 -> 83.013098 | AU10: =AS10/(1+'Input&Output'!$D$33/100)^A10 -> 68.605866 | AW10: =AW9+AS10 -> -45.616462 | AX10: =IF(AND(AW11>0,AW10<0),A10+ABS(AW10/AS11),0) -> 2.6018166 | AZ10: =$AS10/(1+AZ$5)^$A10 -> 83.013098 | BA10: =$AS10/(1+BA$5)^$A10 -> 57.647985 | BB10: =$AS10/(1+BB$5)^$A10 -> 42.353622 | BC10: =$AS10/(1+BC$5)^$A10 -> 32.426992 | BD10: =$AS10/(1+BD$5)^$A10 -> 25.621327 | BE10: =$AS10/(1+BE$5)^$A10 -> 20.753275
A11: 3 | C11: =C10*(1-'Input&Output'!$D$6/100) -> 3.294125 | D11: =C11*'Input&Output'!$D$7/1000 -> 4.9411875 | F11: ='Input&Output'!$D$30*C11 -> 65.8825 | G11: ='Input&Output'!$D$30*D11 -> 98.82375 | I11: =F11+G11 -> 164.70625 | M11: ='Input&Output'!$D$20*(1+('Input&Output'!$G$20/100))^ROW(A3) -> 1.061208 | N11: ='Input&Output'!$D$21*(1+('Input&Output'!$G$21/100))^ROW(A3) -> 3.472875 | O11: ='Input&Output'!$D$22*(1+('Input&Output'!$G$22/100))^ROW(A3) -> 5.95508 | P11: =('Input&Output'!$D$23*'Input&Output'!$D$27*12/1000000)*(1+('Input&Output'!$G$23/100))^ROW(A3) -> 0.37090836 | Q11: =('Input&Output'!$D$24*'Input&Output'!$D$27*365/1000000)*((1+('Input&Output'!$G$24/100))^ROW(A3)) -> 2.91489 | R11: ='Input&Output'!$D$25*((1+('Input&Output'!$G$25/100))^ROW(A3)) -> 2.450086 | S11: ='Input&Output'!$D$10*'Input&Output'!$D$26*(1+('Input&Output'!$G$26/100))^ROW(A3) -> 36.75129 | U11: =SUM(M11:S11) -> 52.976337 | W11: =I11 -> 164.70625 | AG11: =IF(A11<='Input&Output'!$D$38,$K$8/'Input&Output'!$D$38,0) -> 21.9 | AH11: =U11 -> 52.976337 | AK11: =MAX(0,W11-AH11-AG11) -> 89.829913 | AL11: =AK11*('Input&Output'!$D$32/100) -> 35.931965 | AO11: =I11 -> 164.70625 | AQ11: =U11 -> 52.976337 | AR11: =AL11 -> 35.931965 | AS11: =AO11-AP11-AQ11-AR11 -> 75.797948 | AU11: =AS11/(1+'Input&Output'!$D$33/100)^A11 -> 56.94812 | AW11: =AW10+AS11 -> 30.181486 | AX11: =IF(AND(AW12>0,AW11<0),A11+ABS(AW11/AS12),0) -> 0 | AZ11: =$AS11/(1+AZ$5)^$A11 -> 75.797948 | BA11: =$AS11/(1+BA$5)^$A11 -> 43.864553 | BB11: =$AS11/(1+BB$5)^$A11 -> 27.623159 | BC11: =$AS11/(1+BC$5)^$A11 -> 18.505358 | BD11: =$AS11/(1+BD$5)^$A11 -> 12.996905 | BE11: =$AS11/(1+BE$5)^$A11 -> 9.4747434
A12: 4 | C12: =C11*(1-'Input&Output'!$D$6/100) -> 3.1294187 | D12: =C12*'Input&Output'!$D$7/1000 -> 4.6941281 | F12: ='Input&Output'!$D$30*C12 -> 62.588375 | G12: ='Input&Output'!$D$30*D12 -> 93.882562 | I12: =F12+G12 -> 156.47094 | M12: ='Input&Output'!$D$20*(1+('Input&Output'!$G$20/100))^ROW(A4) -> 1.0824322 | N12: ='Input&Output'!$D$21*(1+('Input&Output'!$G$21/100))^ROW(A4) -> 3.6465188 | O12: ='Input&Output'!$D$22*(1+('Input&Output'!$G$22/100))^ROW(A4) -> 6.3123848 | P12: =('Input&Output'!$D$23*'Input&Output'!$D$27*12/1000000)*(1+('Input&Output'!$G$23/100))^ROW(A4) -> 0.37461744 | Q12: =('Input&Output'!$D$24*'Input&Output'!$D$27*365/1000000)*((1+('Input&Output'!$G$24/100))^ROW(A4)) -> 3.206379 | R12: ='Input&Output'!$D$25*((1+('Input&Output'!$G$25/100))^ROW(A4)) -> 2.621592 | S12: ='Input&Output'!$D$10*'Input&Output'!$D$26*(1+('Input&Output'!$G$26/100))^ROW(A4) -> 39.32388 | U12: =SUM(M12:S12) -> 56.567804 | W12: =I12 -> 156.47094 | AG12: =IF(A12<='Input&Output'!$D$38,$K$8/'Input&Output'!$D$38,0) -> 21.9 | AH12: =U12 -> 56.567804 | AK12: =MAX(0,W12-AH12-AG12) -> 78.003133 | AL12: =AK12*('Input&Output'!$D$32/100) -> 31.201253 | AO12: =I12 -> 156.47094 | AQ12: =U12 -> 56.567804 | AR12: =AL12 -> 31.201253 | AS12: =AO12-AP12-AQ12-AR12 -> 68.70188 | AU12: =AS12/(1+'Input&Output'!$D$33/100)^A12 -> 46.924308 | AW12: =AW11+AS12 -> 98.883366 | AX12: =IF(AND(AW13>0,AW12<0),A12+ABS(AW12/AS13),0) -> 0 | AZ12: =$AS12/(1+AZ$5)^$A12 -> 68.70188 | BA12: =$AS12/(1+BA$5)^$A12 -> 33.131694 | BB12: =$AS12/(1+BB$5)^$A12 -> 17.883663 | BC12: =$AS12/(1+BC$5)^$A12 -> 10.483075 | BD12: =$AS12/(1+BD$5)^$A12 -> 6.5445321 | BE12: =$AS12/(1+BE$5)^$A12 -> 4.2938675
A13: 5 | C13: =C12*(1-'Input&Output'!$D$6/100) -> 2.9729478 | D13: =C13*'Input&Output'!$D$7/1000 -> 4.4594217 | F13: ='Input&Output'!$D$30*C13 -> 59.458956 | G13: ='Input&Output'!$D$30*D13 -> 89.188434 | I13: =F13+G13 -> 148.64739 | M13: ='Input&Output'!$D$20*(1+('Input&Output'!$G$20/100))^ROW(A5) -> 1.1040808 | N13: ='Input&Output'!$D$21*(1+('Input&Output'!$G$21/100))^ROW(A5) -> 3.8288447 | O13: ='Input&Output'!$D$22*(1+('Input&Output'!$G$22/100))^ROW(A5) -> 6.6911279 | P13: =('Input&Output'!$D$23*'Input&Output'!$D$27*12/1000000)*(1+('Input&Output'!$G$23/100))^ROW(A5) -> 0.37836362 | Q13: =('Input&Output'!$D$24*'Input&Output'!$D$27*365/1000000)*((1+('Input&Output'!$G$24/100))^ROW(A5)) -> 3.5270169 | R13: ='Input&Output'!$D$25*((1+('Input&Output'!$G$25/100))^ROW(A5)) -> 2.8051035 | S13: ='Input&Output'!$D$10*'Input&Output'!$D$26*(1+('Input&Output'!$G$26/100))^ROW(A5) -> 42.076552 | U13: =SUM(M13:S13) -> 60.411089 | W13: =I13 -> 148.64739 | AG13: =IF(A13<='Input&Output'!$D$38,$K$8/'Input&Output'!$D$38,0) -> 21.9 | AH13: =U13 -> 60.411089 | AK13: =MAX(0,W13-AH13-AG13) -> 66.336301 | AL13: =AK13*('Input&Output'!$D$32/100) -> 26.534521 | AO13: =I13 -> 148.64739 | AQ13: =U13 -> 60.411089 | AR13: =AL13 -> 26.534521 | AS13: =AO13-AP13-AQ13-AR13 -> 61.701781 | AU13: =AS13/(1+'Input&Output'!$D$33/100)^A13 -> 38.311951 | AW13: =AW12+AS13 -> 160.58515 | AX13: =IF(AND(AW14>0,AW13<0),A13+ABS(AW13/AS14),0) -> 0 | AZ13: =$AS13/(1+AZ$5)^$A13 -> 61.701781 | BA13: =$AS13/(1+BA$5)^$A13 -> 24.796562 | BB13: =$AS13/(1+BB$5)^$A13 -> 11.472486 | BC13: =$AS13/(1+BC$5)^$A13 -> 5.8843404 | BD13: =$AS13/(1+BD$5)^$A13 -> 3.2653909 | BE13: =$AS13/(1+BE$5)^$A13 -> 1.9281807
A14: 6 | C14: =C13*(1-'Input&Output'!$D$6/100) -> 2.8243004 | D14: =C14*'Input&Output'!$D$7/1000 -> 4.2364506 | F14: ='Input&Output'!$D$30*C14 -> 56.486008 | G14: ='Input&Output'!$D$30*D14 -> 84.729013 | I14: =F14+G14 -> 141.21502 | M14: ='Input&Output'!$D$20*(1+('Input&Output'!$G$20/100))^ROW(A6) -> 1.1261624 | N14: ='Input&Output'!$D$21*(1+('Input&Output'!$G$21/100))^ROW(A6) -> 4.0202869 | O14: ='Input&Output'!$D$22*(1+('Input&Output'!$G$22/100))^ROW(A6) -> 7.0925956 | P14: =('Input&Output'!$D$23*'Input&Output'!$D$27*12/1000000)*(1+('Input&Output'!$G$23/100))^ROW(A6) -> 0.38214725 | Q14: =('Input&Output'!$D$24*'Input&Output'!$D$27*365/1000000)*((1+('Input&Output'!$G$24/100))^ROW(A6)) -> 3.8797186 | R14: ='Input&Output'!$D$25*((1+('Input&Output'!$G$25/100))^ROW(A6)) -> 3.0014607 | S14: ='Input&Output'!$D$10*'Input&Output'!$D$26*(1+('Input&Output'!$G$26/100))^ROW(A6) -> 45.021911 | U14: =SUM(M14:S14) -> 64.524282 | W14: =I14 -> 141.21502 | AG14: =IF(A14<='Input&Output'!$D$38,$K$8/'Input&Output'!$D$38,0) -> 21.9 | AH14: =U14 -> 64.524282 | AK14: =MAX(0,W14-AH14-AG14) -> 54.790739 | AL14: =AK14*('Input&Output'!$D$32/100) -> 21.916296 | AO14: =I14 -> 141.21502 | AQ14: =U14 -> 64.524282 | AR14: =AL14 -> 21.916296 | AS14: =AO14-AP14-AQ14-AR14 -> 54.774443 | AU14: =AS14/(1+'Input&Output'!$D$33/100)^A14 -> 30.918745 | AW14: =AW13+AS14 -> 215.35959 | AX14: =IF(AND(AW15>0,AW14<0),A14+ABS(AW14/AS15),0) -> 0 | AZ14: =$AS14/(1+AZ$5)^$A14 -> 54.774443 | BA14: =$AS14/(1+BA$5)^$A14 -> 18.34385 | BB14: =$AS14/(1+BB$5)^$A14 -> 7.2746107 | BC14: =$AS14/(1+BC$5)^$A14 -> 3.2648112 | BD14: =$AS14/(1+BD$5)^$A14 -> 1.610434 | BE14: =$AS14/(1+BE$5)^$A14 -> 0.85585068
A15: 7 | C15: =C14*(1-'Input&Output'!$D$6/100) -> 2.6830854 | D15: =C15*'Input&Output'!$D$7/1000 -> 4.0246281 | F15: ='Input&Output'!$D$30*C15 -> 53.661708 | G15: ='Input&Output'!$D$30*D15 -> 80.492562 | I15: =F15+G15 -> 134.15427 | M15: ='Input&Output'!$D$20*(1+('Input&Output'!$G$20/100))^ROW(A7) -> 1.1486857 | N15: ='Input&Output'!$D$21*(1+('Input&Output'!$G$21/100))^ROW(A7) -> 4.2213013 | O15: ='Input&Output'!$D$22*(1+('Input&Output'!$G$22/100))^ROW(A7) -> 7.5181513 | P15: =('Input&Output'!$D$23*'Input&Output'!$D$27*12/1000000)*(1+('Input&Output'!$G$23/100))^ROW(A7) -> 0.38596873 | Q15: =('Input&Output'!$D$24*'Input&Output'!$D$27*365/1000000)*((1+('Input&Output'!$G$24/100))^ROW(A7)) -> 4.2676904 | R15: ='Input&Output'!$D$25*((1+('Input&Output'!$G$25/100))^ROW(A7)) -> 3.211563 | S15: ='Input&Output'!$D$10*'Input&Output'!$D$26*(1+('Input&Output'!$G$26/100))^ROW(A7) -> 48.173444 | U15: =SUM(M15:S15) -> 68.926805 | W15: =I15 -> 134.15427 | AG15: =IF(A15<='Input&Output'!$D$38,$K$8/'Input&Output'!$D$38,0) -> 21.9 | AH15: =U15 -> 68.926805 | AK15: =MAX(0,W15-AH15-AG15) -> 43.327465 | AL15: =AK15*('Input&Output'!$D$32/100) -> 17.330986 | AO15: =I15 -> 134.15427 | AQ15: =U15 -> 68.926805 | AR15: =AL15 -> 17.330986 | AS15: =AO15-AP15-AQ15-AR15 -> 47.896479 | AU15: =AS15/(1+'Input&Output'!$D$33/100)^A15 -> 24.578467 | AW15: =AW14+AS15 -> 263.25607 | AX15: =IF(AND(AW16>0,AW15<0),A15+ABS(AW15/AS16),0) -> 0 | AZ15: =$AS15/(1+AZ$5)^$A15 -> 47.896479 | BA15: =$AS15/(1+BA$5)^$A15 -> 13.367028 | BB15: =$AS15/(1+BB$5)^$A15 -> 4.5436758 | BC15: =$AS15/(1+BC$5)^$A15 -> 1.7842829 | BD15: =$AS15/(1+BD$5)^$A15 -> 0.78234094 | BE15: =$AS15/(1+BE$5)^$A15 -> 0.37419124
A16: 8 | C16: =C15*(1-'Input&Output'!$D$6/100) -> 2.5489311 | D16: =C16*'Input&Output'!$D$7/1000 -> 3.8233967 | F16: ='Input&Output'!$D$30*C16 -> 50.978623 | G16: ='Input&Output'!$D$30*D16 -> 76.467934 | I16: =F16+G16 -> 127.44656 | M16: ='Input&Output'!$D$20*(1+('Input&Output'!$G$20/100))^ROW(A8) -> 1.1716594 | N16: ='Input&Output'!$D$21*(1+('Input&Output'!$G$21/100))^ROW(A8) -> 4.4323663 | O16: ='Input&Output'!$D$22*(1+('Input&Output'!$G$22/100))^ROW(A8) -> 7.9692404 | P16: =('Input&Output'!$D$23*'Input&Output'!$D$27*12/1000000)*(1+('Input&Output'!$G$23/100))^ROW(A8) -> 0.38982841 | Q16: =('Input&Output'!$D$24*'Input&Output'!$D$27*365/1000000)*((1+('Input&Output'!$G$24/100))^ROW(A8)) -> 4.6944595 | R16: ='Input&Output'!$D$25*((1+('Input&Output'!$G$25/100))^ROW(A8)) -> 3.4363724 | S16: ='Input&Output'!$D$10*'Input&Output'!$D$26*(1+('Input&Output'!$G$26/100))^ROW(A8) -> 51.545585 | U16: =SUM(M16:S16) -> 73.639512 | W16: =I16 -> 127.44656 | AG16: =IF(A16<='Input&Output'!$D$38,$K$8/'Input&Output'!$D$38,0) -> 21.9 | AH16: =U16 -> 73.639512 | AK16: =MAX(0,W16-AH16-AG16) -> 31.907045 | AL16: =AK16*('Input&Output'!$D$32/100) -> 12.762818 | AO16: =I16 -> 127.44656 | AQ16: =U16 -> 73.639512 | AR16: =AL16 -> 12.762818 | AS16: =AO16-AP16-AQ16-AR16 -> 41.044227 | AU16: =AS16/(1+'Input&Output'!$D$33/100)^A16 -> 19.147435 | AW16: =AW15+AS16 -> 304.3003 | AX16: =IF(AND(AW17>0,AW16<0),A16+ABS(AW16/AS17),0) -> 0 | AZ16: =$AS16/(1+AZ$5)^$A16 -> 41.044227 | BA16: =$AS16/(1+BA$5)^$A16 -> 9.5455754 | BB16: =$AS16/(1+BB$5)^$A16 -> 2.7811717 | BC16: =$AS16/(1+BC$5)^$A16 -> 0.95563538 | BD16: =$AS16/(1+BD$5)^$A16 -> 0.37245348 | BE16: =$AS16/(1+BE$5)^$A16 -> 0.16032901
A17: 9 | C17: =C16*(1-'Input&Output'!$D$6/100) -> 2.4214846 | D17: =C17*'Input&Output'!$D$7/1000 -> 3.6322269 | F17: ='Input&Output'!$D$30*C17 -> 48.429691 | G17: ='Input&Output'!$D$30*D17 -> 72.644537 | I17: =F17+G17 -> 121.07423 | M17: ='Input&Output'!$D$20*(1+('Input&Output'!$G$20/100))^ROW(A9) -> 1.1950926 | N17: ='Input&Output'!$D$21*(1+('Input&Output'!$G$21/100))^ROW(A9) -> 4.6539846 | O17: ='Input&Output'!$D$22*(1+('Input&Output'!$G$22/100))^ROW(A9) -> 8.4473948 | P17: =('Input&Output'!$D$23*'Input&Output'!$D$27*12/1000000)*(1+('Input&Output'!$G$23/100))^ROW(A9) -> 0.3937267 | Q17: =('Input&Output'!$D$24*'Input&Output'!$D$27*365/1000000)*((1+('Input&Output'!$G$24/100))^ROW(A9)) -> 5.1639054 | R17: ='Input&Output'!$D$25*((1+('Input&Output'!$G$25/100))^ROW(A9)) -> 3.6769184 | S17: ='Input&Output'!$D$10*'Input&Output'!$D$26*(1+('Input&Output'!$G$26/100))^ROW(A9) -> 55.153776 | U17: =SUM(M17:S17) -> 78.684799 | W17: =I17 -> 121.07423 | AG17: =IF(A17<='Input&Output'!$D$38,$K$8/'Input&Output'!$D$38,0) -> 21.9 | AH17: =U17 -> 78.684799 | AK17: =MAX(0,W17-AH17-AG17) -> 20.48943 | AL17: =AK17*('Input&Output'!$D$32/100) -> 8.1957719 | AO17: =I17 -> 121.07423 | AQ17: =U17 -> 78.684799 | AR17: =AL17 -> 8.1957719 | AS17: =AO17-AP17-AQ17-AR17 -> 34.193658 | AU17: =AS17/(1+'Input&Output'!$D$33/100)^A17 -> 14.501449 | AW17: =AW16+AS17 -> 338.49395 | AX17: =IF(AND(AW18>0,AW17<0),A17+ABS(AW17/AS18),0) -> 0 | AZ17: =$AS17/(1+AZ$5)^$A17 -> 34.193658 | BA17: =$AS17/(1+BA$5)^$A17 -> 6.62696 | BB17: =$AS17/(1+BB$5)^$A17 -> 1.6549819 | BC17: =$AS17/(1+BC$5)^$A17 -> 0.49758321 | BD17: =$AS17/(1+BD$5)^$A17 -> 0.17238244 | BE17: =$AS17/(1+BE$5)^$A17 -> 0.066784488
A18: 10 | C18: =C17*(1-'Input&Output'!$D$6/100) -> 2.3004103 | D18: =C18*'Input&Output'!$D$7/1000 -> 3.4506155 | F18: ='Input&Output'!$D$30*C18 -> 46.008207 | G18: ='Input&Output'!$D$30*D18 -> 69.01231 | I18: =F18+G18 -> 115.02052 | M18: ='Input&Output'!$D$20*(1+('Input&Output'!$G$20/100))^ROW(A10) -> 1.2189944 | N18: ='Input&Output'!$D$21*(1+('Input&Output'!$G$21/100))^ROW(A10) -> 4.8866839 | O18: ='Input&Output'!$D$22*(1+('Input&Output'!$G$22/100))^ROW(A10) -> 8.9542385 | P18: =('Input&Output'!$D$23*'Input&Output'!$D$27*12/1000000)*(1+('Input&Output'!$G$23/100))^ROW(A10) -> 0.39766397 | Q18: =('Input&Output'!$D$24*'Input&Output'!$D$27*365/1000000)*((1+('Input&Output'!$G$24/100))^ROW(A10)) -> 5.680296 | R18: ='Input&Output'!$D$25*((1+('Input&Output'!$G$25/100))^ROW(A10)) -> 3.9343027 | S18: ='Input&Output'!$D$10*'Input&Output'!$D$26*(1+('Input&Output'!$G$26/100))^ROW(A10) -> 59.014541 | U18: =SUM(M18:S18) -> 84.08672 | W18: =I18 -> 115.02052 | AG18: =IF(A18<='Input&Output'!$D$38,$K$8/'Input&Output'!$D$38,0) -> 21.9 | AH18: =U18 -> 84.08672 | AK18: =MAX(0,W18-AH18-AG18) -> 9.0337971 | AL18: =AK18*('Input&Output'!$D$32/100) -> 3.6135188 | AO18: =I18 -> 115.02052 | AQ18: =U18 -> 84.08672 | AR18: =AL18 -> 3.6135188 | AS18: =AO18-AP18-AQ18-AR18 -> 27.320278 | AU18: =AS18/(1+'Input&Output'!$D$33/100)^A18 -> 10.53315 | AW18: =AW17+AS18 -> 365.81423 | AX18: =IF(AND(AW19>0,AW18<0),A18+ABS(AW18/AS19),0) -> 0 | AZ18: =$AS18/(1+AZ$5)^$A18 -> 27.320278 | BA18: =$AS18/(1+BA$5)^$A18 -> 4.4123775 | BB18: =$AS18/(1+BB$5)^$A18 -> 0.94450609 | BC18: =$AS18/(1+BC$5)^$A18 -> 0.24847648 | BD18: =$AS18/(1+BD$5)^$A18 -> 0.076517376 | BE18: =$AS18/(1+BE$5)^$A18 -> 0.026679959
A19: 11 | C19: =C18*(1-'Input&Output'!$D$6/100) -> 2.1853898 | D19: =C19*'Input&Output'!$D$7/1000 -> 3.2780847 | F19: ='Input&Output'!$D$30*C19 -> 43.707797 | G19: ='Input&Output'!$D$30*D19 -> 65.561695 | I19: =F19+G19 -> 109.26949 | M19: ='Input&Output'!$D$20*(1+('Input&Output'!$G$20/100))^ROW(A11) -> 1.2433743 | N19: ='Input&Output'!$D$21*(1+('Input&Output'!$G$21/100))^ROW(A11) -> 5.1310181 | O19: ='Input&Output'!$D$22*(1+('Input&Output'!$G$22/100))^ROW(A11) -> 9.4914928 | P19: =('Input&Output'!$D$23*'Input&Output'!$D$27*12/1000000)*(1+('Input&Output'!$G$23/100))^ROW(A11) -> 0.4016406 | Q19: =('Input&Output'!$D$24*'Input&Output'!$D$27*365/1000000)*((1+('Input&Output'!$G$24/100))^ROW(A11)) -> 6.2483256 | R19: ='Input&Output'!$D$25*((1+('Input&Output'!$G$25/100))^ROW(A11)) -> 4.2097039 | S19: ='Input&Output'!$D$10*'Input&Output'!$D$26*(1+('Input&Output'!$G$26/100))^ROW(A11) -> 63.145559 | U19: =SUM(M19:S19) -> 89.871114 | W19: =I19 -> 109.26949 | AG19: =IF(A19<='Input&Output'!$D$38,$K$8/'Input&Output'!$D$38,0) -> 0 | AH19: =U19 -> 89.871114 | AK19: =MAX(0,W19-AH19-AG19) -> 19.398378 | AL19: =AK19*('Input&Output'!$D$32/100) -> 7.759351 | AO19: =I19 -> 109.26949 | AQ19: =U19 -> 89.871114 | AR19: =AL19 -> 7.759351 | AS19: =AO19-AP19-AQ19-AR19 -> 11.639027 | AU19: =AS19/(1+'Input&Output'!$D$33/100)^A19 -> 4.0794078 | AW19: =AW18+AS19 -> 377.45326 | AX19: =IF(AND(AW20>0,AW19<0),A19+ABS(AW19/AS20),0) -> 0 | AZ19: =$AS19/(1+AZ$5)^$A19 -> 11.639027 | BA19: =$AS19/(1+BA$5)^$A19 -> 1.5664731 | BB19: =$AS19/(1+BB$5)^$A19 -> 0.28741423 | BC19: =$AS19/(1+BC$5)^$A19 -> 0.066160206 | BD19: =$AS19/(1+BD$5)^$A19 -> 0.018110027 | BE19: =$AS19/(1+BE$5)^$A19 -> 0.0056831184
A20: 12 | C20: =C19*(1-'Input&Output'!$D$6/100) -> 2.0761203 | D20: =C20*'Input&Output'!$D$7/1000 -> 3.1141805 | F20: ='Input&Output'!$D$30*C20 -> 41.522407 | G20: ='Input&Output'!$D$30*D20 -> 62.28361 | I20: =F20+G20 -> 103.80602 | M20: ='Input&Output'!$D$20*(1+('Input&Output'!$G$20/100))^ROW(A12) -> 1.2682418 | N20: ='Input&Output'!$D$21*(1+('Input&Output'!$G$21/100))^ROW(A12) -> 5.387569 | O20: ='Input&Output'!$D$22*(1+('Input&Output'!$G$22/100))^ROW(A12) -> 10.060982 | P20: =('Input&Output'!$D$23*'Input&Output'!$D$27*12/1000000)*(1+('Input&Output'!$G$23/100))^ROW(A12) -> 0.40565701 | Q20: =('Input&Output'!$D$24*'Input&Output'!$D$27*365/1000000)*((1+('Input&Output'!$G$24/100))^ROW(A12)) -> 6.8731581 | R20: ='Input&Output'!$D$25*((1+('Input&Output'!$G$25/100))^ROW(A12)) -> 4.5043832 | S20: ='Input&Output'!$D$10*'Input&Output'!$D$26*(1+('Input&Output'!$G$26/100))^ROW(A12) -> 67.565748 | U20: =SUM(M20:S20) -> 96.065739 | W20: =I20 -> 103.80602 | AG20: =IF(A20<='Input&Output'!$D$38,$K$8/'Input&Output'!$D$38,0) -> 0 | AH20: =U20 -> 96.065739 | AK20: =MAX(0,W20-AH20-AG20) -> 7.7402777 | AL20: =AK20*('Input&Output'!$D$32/100) -> 3.0961111 | AO20: =I20 -> 103.80602 | AQ20: =U20 -> 96.065739 | AR20: =AL20 -> 3.0961111 | AS20: =AO20-AP20-AQ20-AR20 -> 4.6441666 | AU20: =AS20/(1+'Input&Output'!$D$33/100)^A20 -> 1.4797746 | AW20: =AW19+AS20 -> 382.09743 | AX20: =IF(AND(AW21>0,AW20<0),A20+ABS(AW20/AS21),0) -> 0 | AZ20: =$AS20/(1+AZ$5)^$A20 -> 4.6441666 | BA20: =$AS20/(1+BA$5)^$A20 -> 0.52087419 | BB20: =$AS20/(1+BB$5)^$A20 -> 0.081916496 | BC20: =$AS20/(1+BC$5)^$A20 -> 0.016499394 | BD20: =$AS20/(1+BD$5)^$A20 -> 0.004014558 | BE20: =$AS20/(1+BE$5)^$A20 -> 0.0011338297
A21: 13 | C21: =C20*(1-'Input&Output'!$D$6/100) -> 1.9723143 | D21: =C21*'Input&Output'!$D$7/1000 -> 2.9584715 | F21: ='Input&Output'!$D$30*C21 -> 39.446286 | G21: ='Input&Output'!$D$30*D21 -> 59.16943 | I21: =F21+G21 -> 98.615716 | M21: ='Input&Output'!$D$20*(1+('Input&Output'!$G$20/100))^ROW(A13) -> 1.2936066 | N21: ='Input&Output'!$D$21*(1+('Input&Output'!$G$21/100))^ROW(A13) -> 5.6569474 | O21: ='Input&Output'!$D$22*(1+('Input&Output'!$G$22/100))^ROW(A13) -> 10.664641 | P21: =('Input&Output'!$D$23*'Input&Output'!$D$27*12/1000000)*(1+('Input&Output'!$G$23/100))^ROW(A13) -> 0.40971358 | Q21: =('Input&Output'!$D$24*'Input&Output'!$D$27*365/1000000)*((1+('Input&Output'!$G$24/100))^ROW(A13)) -> 7.560474 | R21: ='Input&Output'!$D$25*((1+('Input&Output'!$G$25/100))^ROW(A13)) -> 4.81969 | S21: ='Input&Output'!$D$10*'Input&Output'!$D$26*(1+('Input&Output'!$G$26/100))^ROW(A13) -> 72.29535 | U21: =SUM(M21:S21) -> 102.70042 | W21: =I21 -> 98.615716 | AG21: =IF(A21<='Input&Output'!$D$38,$K$8/'Input&Output'!$D$38,0) -> 0 | AH21: =U21 -> 102.70042 | AK21: =MAX(0,W21-AH21-AG21) -> 0 | AL21: =AK21*('Input&Output'!$D$32/100) -> 0 | AO21: =I21 -> 98.615716 | AQ21: =U21 -> 102.70042 | AR21: =AL21 -> 0 | AS21: =AO21-AP21-AQ21-AR21 -> -4.0847069 | AU21: =AS21/(1+'Input&Output'!$D$33/100)^A21 -> -1.1831941 | AW21: =AW20+AS21 -> 378.01272 | AX21: =IF(AND(AW22>0,AW21<0),A21+ABS(AW21/AS22),0) -> 0 | AZ21: =$AS21/(1+AZ$5)^$A21 -> -4.0847069 | BA21: =$AS21/(1+BA$5)^$A21 -> -0.38177255 | BB21: =$AS21/(1+BB$5)^$A21 -> -0.051463158 | BC21: =$AS21/(1+BC$5)^$A21 -> -0.0090698713 | BD21: =$AS21/(1+BD$5)^$A21 -> -0.0019616356 | BE21: =$AS21/(1+BE$5)^$A21 -> -0.00049862145
... A28: 20 | C28: =C27*(1-'Input&Output'!$D$6/100) -> 1.3773406 | D28: =C28*'Input&Output'!$D$7/1000 -> 2.066011 | F28: ='Input&Output'!$D$30*C28 -> 27.546813 | G28: ='Input&Output'!$D$30*D28 -> 41.320219 | I28: =F28+G28 -> 68.867032 | M28: ='Input&Output'!$D$20*(1+('Input&Output'!$G$20/100))^ROW(A20) -> 1.4859474 | N28: ='Input&Output'!$D$21*(1+('Input&Output'!$G$21/100))^ROW(A20) -> 7.9598931 | O28: ='Input&Output'!$D$22*(1+('Input&Output'!$G$22/100))^ROW(A20) -> 16.035677 | P28: =('Input&Output'!$D$23*'Input&Output'!$D$27*12/1000000)*(1+('Input&Output'!$G$23/100))^ROW(A20) -> 0.43926841 | Q28: =('Input&Output'!$D$24*'Input&Output'!$D$27*365/1000000)*((1+('Input&Output'!$G$24/100))^ROW(A20)) -> 14.733225 | R28: ='Input&Output'!$D$25*((1+('Input&Output'!$G$25/100))^ROW(A20)) -> 7.7393689 | S28: ='Input&Output'!$D$10*'Input&Output'!$D$26*(1+('Input&Output'!$G$26/100))^ROW(A20) -> 116.09053 | U28: =SUM(M28:S28) -> 164.48391 | W28: =I28 -> 68.867032 | AG28: =IF(A28<='Input&Output'!$D$38,$K$8/'Input&Output'!$D$38,0) -> 0 | AH28: =U28 -> 164.48391 | AK28: =MAX(0,W28-AH28-AG28) -> 0 | AL28: =AK28*('Input&Output'!$D$32/100) -> 0 | AO28: =I28 -> 68.867032 | AQ28: =U28 -> 164.48391 | AR28: =AL28 -> 0 | AS28: =AO28-AP28-AQ28-AR28 -> -95.616882 | AU28: =AS28/(1+'Input&Output'!$D$33/100)^A28 -> -14.21284 | AW28: =AW27+AS28 -> -5.7771805 | AX28: =IF(AND(AW29>0,AW28<0),A28+ABS(AW28/AS29),0) -> 0 | AZ28: =$AS28/(1+AZ$5)^$A28 -> -95.616882 | BA28: =$AS28/(1+BA$5)^$A28 -> -2.4940758 | BB28: =$AS28/(1+BB$5)^$A28 -> -0.11428096 | BC28: =$AS28/(1+BC$5)^$A28 -> -0.0079092431 | BD28: =$AS28/(1+BD$5)^$A28 -> -0.00075004008 | BE28: =$AS28/(1+BE$5)^$A28 -> -9.1187364e-05
A30: Total | C30: =SUM(C9:C29) -> 46.830528 | D30: =SUM(D9:D29) -> 70.245791 | F30: =SUM(F9:F29) -> 936.61055 | G30: =SUM(G9:G29) -> 1404.9158 | I30: =SUM(I9:I29) -> 2341.5264 | M30: =SUM(M9:M29) -> 24.783317 | N30: =SUM(N9:N29) -> 104.15776 | O30: =SUM(O9:O29) -> 194.96363 | P30: =SUM(P9:P29) -> 8.0061099 | Q30: =SUM(Q9:Q29) -> 137.97547 | R30: =SUM(R9:R29) -> 87.730354 | S30: =SUM(S9:S29) -> 1315.9553 | U30: =SUM(U9:U29) -> 1873.5719 | W30: =SUM(W9:W29) -> 2341.5264 | AG30: =SUM(AG9:AG29) -> 219 | AH30: =SUM(AH9:AH29) -> 1873.5719 | AI30: =SUM(AI9:AI29) -> 0 | AK30: =SUM(AK9:AK29) -> 636.82904 | AL30: =SUM(AL9:AL29) -> 254.73162 | AM30: Total | AO30: =SUM(AO8:AO29) -> 2341.5264 | AP30: =SUM(AP8:AP29) -> 219 | AQ30: =SUM(AQ8:AQ29) -> 1873.5719 | AR30: =SUM(AR8:AR29) -> 254.73162 | AS30: =SUM(AS8:AS29) -> -5.7771805 | AU30: =SUM(AU8:AU29) -> 107.7269 | AX30: =SUM(AX8:AX29) -> 2.6018166 | AZ30: =SUM(AZ8:AZ29) -> -5.7771805 | BA30: =SUM(BA8:BA29) -> 54.4303 | BB30: =SUM(BB8:BB29) -> -38.701214 | BC30: =SUM(BC8:BC29) -> -88.514818 | BD30: =SUM(BD8:BD29) -> -117.34973 | BE30: =SUM(BE8:BE29) -> -135.87795
AS32: NPV = | AU32: =AU30 -> 107.7269 | AV32: MM
AS33: IRR = | AU33: =IRR(AS8:AS28) -> 0.30189958
AS34: Payback = | AU34: =AX30 -> 2.6018166 | AV34: Years
AS35: CPI = | AU35: =AU32/AP8 -> 0.49190365 | AV35: $/$

Sheet Prod.=max
A1: CASH FLOW ANALYSIS ($MM) | AM1: CASH FLOW ANALYSIS
AM2: (Table 2)
A4: Years | C4: Annual Production | F4: Revenue | K4: CAPEX | M4: OPEX | W4: Tax Calculation | AM4: Years | AO4: Cash Flow | AW4: Cum. | AX4: Payback | AZ4: Discounted NCF
C5: Oil | D5: Gas | F5: Oil | G5: Gas | I5: Total | M5: Fuel | N5: Spares | O5: Maint. | P5: Salaries | Q5: Serv. | R5: O/H | S5: Wells | U5: Total | W5: Revenue | X5: St. Line | Y5: DB w/Balloon | AA5: Dec | AB5: DDBw/Balloon | AD5: Double | AE5: SYD | AF5: Unit of Prod | AG5: Dep. | AH5: Opex | AI5: Net Rev. | AJ5: W/LCF | AK5: Income | AL5: Tax | AO5: Revenue | AP5: Capex | AQ5: Opex | AR5: Tax | AS5: NCF | AU5: NPV | AW5: CF | AX5: (Years) | AZ5: 0 | BA5: 0.2 | BB5: 0.4 | BC5: 0.6 | BD5: 0.8 | BE5: 1
C6: (MMB) | D6: (BCF) | Y6: Bal | Z6: Dep | AA6: Bal | AB6: Bal | AC6: Dep | AD6: Dec. Bal
A8: 0 | K8: =SUM(('Input&Output'!$D$10*'Input&Output'!$D$11)+(('Input&Output'!$D$12*('Input&Output'!$D$13+'Input&Output'!$D$14)*'Input&Output'!$D$15)/1000000)+('Input&Output'!$D$16)+('Input&Output'!$D$17)) -> 219 | M8: ='Input&Output'!D20 -> 1 | N8: ='Input&Output'!D21 -> 3 | O8: ='Input&Output'!D22 -> 5 | P8: ='Input&Output'!D23 -> 1000 | Q8: ='Input&Output'!D24 -> 200 | R8: ='Input&Output'!D25 -> 2 | S8: {='Cash Flow'!S8:S28} -> 30 | AM8: 0 | AP8: =K8 -> 219 | AS8: =AO8-AP8-AQ8-AR8 -> -219 | AU8: =AS8/(1+'Input&Output'!$D$33/100)^A8 -> -219 | AW8: =AS8 -> -219 | AX8: =IF(AND(AW8>0,AW7<0),A7+ABS(AW7/AS8),0) -> 0 | AZ8: =$AS8/(1+AZ$5)^$A8 -> -219 | BA8: =$AS8/(1+BA$5)^$A8 -> -219 | BB8: =$AS8/(1+BB$5)^$A8 -> -219 | BC8: =$AS8/(1+BC$5)^$A8 -> -219 | BD8: =$AS8/(1+BD$5)^$A8 -> -219 | BE8: =$AS8/(1+BE$5)^$A8 -> -219
A9: 1 | C9: ='Input&Output'!$D$5*365*(1+'Input&Output'!E53/100)/1000 -> 8.03 | D9: =C9*'Input&Output'!$D$7/1000 -> 12.045 | F9: ='Input&Output'!$D$30*C9 -> 160.6 | G9: ='Input&Output'!$D$30*D9 -> 240.9 | I9: =F9+G9 -> 401.5 | M9: ='Input&Output'!$D$20*(1+('Input&Output'!$G$20/100))^ROW(A1) -> 1.02 | N9: ='Input&Output'!$D$21*(1+('Input&Output'!$G$21/100))^ROW(A1) -> 3.15 | O9: ='Input&Output'!$D$22*(1+('Input&Output'!$G$22/100))^ROW(A1) -> 5.3 | P9: =('Input&Output'!$D$23*'Input&Output'!$D$27*12/1000000)*(1+('Input&Output'!$G$23/100))^ROW(A1) -> 0.3636 | Q9: =('Input&Output'!$D$24*'Input&Output'!$D$27*365/1000000)*((1+('Input&Output'!$G$24/100))^ROW(A1)) -> 2.409 | R9: ='Input&Output'!$D$25*((1+('Input&Output'!$G$25/100))^ROW(A1)) -> 2.14 | S9: 32.1 | U9: {='Cash Flow'!U9:U28} -> 46.4826 | W9: {='Prod.=0.5'!W9:W28} -> 182.5 | AG9: =IF(A9<='Input&Output'!$D$38,$K$8/'Input&Output'!$D$38,0) -> 21.9 | AH9: {=U9:U28} -> 46.4826 | AK9: =MAX(0,W9-AH9-AG9) -> 114.1174 | AL9: =AK9*('Input&Output'!$D$32/100) -> 45.64696 | AO9: {=W9:W28} -> 182.5 | AQ9: {=U9:U28} -> 46.4826 | AR9: {=AL9:AL28} -> 45.64696 | AS9: =AO9-AP9-AQ9-AR9 -> 90.37044 | AU9: =AS9/(1+'Input&Output'!$D$33/100)^A9 -> 82.154945 | AW9: =AW8+AS9 -> -128.62956 | AX9: =IF(AND(AW9>0,AW8<0),A8+ABS(AW8/AS9),0) -> 0 | AZ9: =$AS9/(1+AZ$5)^$A9 -> 90.37044 | BA9: =$AS9/(1+BA$5)^$A9 -> 75.3087 | BB9: =$AS9/(1+BB$5)^$A9 -> 64.550314 | BC9: =$AS9/(1+BC$5)^$A9 -> 56.481525 | BD9: =$AS9/(1+BD$5)^$A9 -> 50.2058 | BE9: =$AS9/(1+BE$5)^$A9 -> 45.18522
